<?xml version="1.0"?>
<robot xmlns:controller="http://playerstage.sourceforge.net/gazebo/xmlschema/#controller"
  xmlns:interface="http://playerstage.sourceforge.net/gazebo/xmlschema/#interface"
  xmlns:sensor="http://playerstage.sourceforge.net/gazebo/xmlschema/#sensor"
  xmlns:xacro="http://ros.org/wiki/xacro">

  <xacro:macro name="xbot2_base">
  <link name="base_footprint"/>
  <joint name="base_footprint_to_base" type="fixed">
    <axis rpy="0 0 0" xyz="0 0 0"/>
    <parent link="base_footprint"/>
    <child link="base_link"/>
    <origin rpy="0 0 0" xyz="0 0 0"/>
  </joint>

  <link name="base_link">
    <inertial>
      <origin  xyz="0 0 0.13" rpy="0 0 0" />
      <mass value="25.0" />
      <inertia ixx=".734" ixy="0" ixz="0" iyy=".734" iyz=".0" izz=".156" />
    </inertial>
    <visual>
      <origin xyz="0 0 0" rpy="0 0 0" />
      <geometry>
        <mesh filename="package://robot_sim_demo/meshes/base_link.dae" />
      </geometry>
    </visual>
    <collision>
      <origin xyz="0 0 0" rpy="0 0 0" />
      <geometry>
        <mesh filename="package://robot_sim_demo/meshes/base_link.dae" />
      </geometry>
    </collision>
  </link>

  <link name="laser_mount_link"/>
  <joint name="base_to_laser" type="fixed">
    <axis rpy="0 0 0" xyz="0 0 0"/>
    <parent link="base_link"/>
    <child link="laser_mount_link"/>
    <origin rpy="0 3.1416 3.1416" xyz=".148 0 .253"/>
  </joint>


  <link name="left_wheel">
    <collision name="collision">
      <origin xyz="0 0 0" rpy="1.5708 0 0"/>
      <geometry>
        <cylinder radius="0.095" length="0.04"/>
      </geometry>
    </collision>
    <visual name="left_wheel_visual">
      <origin xyz="0 0 0" rpy="0 0 -1.5708"/>
      <geometry>
        <mesh filename="package://robot_sim_demo/meshes/wheel.dae" />
      </geometry>
    </visual>
    <inertial>
      <origin xyz="0 0 0" rpy="0 0 -1.5708"/>
      <mass value="1.5"/>
      <inertia ixx=".001" ixy="0" ixz="0" iyy=".001" iyz="0" izz=".001" />
    </inertial>
  </link>

  <joint type="continuous" name="left_wheel_hinge">
    <axis xyz="0 1 0" rpy="0 0 0"/>
    <origin xyz="0 0.245 .095" rpy="0 0 0"/>
    <parent link="base_link"/>
    <child link="left_wheel"/>
    <limit effort="5.2" velocity="21.05"/>
    <joint_properties damping="0.0" friction="0.0"/>
  </joint>

  <link name="right_wheel">
    <collision name="collision">
      <origin xyz="0 0 0" rpy="-1.5708  0 0"/>
      <geometry>
        <cylinder radius="0.095" length="0.04"/>
      </geometry>
    </collision>
    <visual name="right_wheel_visual">
      <origin xyz="0 0 0" rpy="0 0 1.5708"/>
      <geometry>
        <mesh filename="package://robot_sim_demo/meshes/wheel.dae" />
      </geometry>
    </visual>
    <inertial>
      <origin xyz="0 0 0" rpy="0 0 1.5708"/>
      <mass value="1.5"/>
      <inertia ixx=".001" ixy="0" ixz="0" iyy=".001" iyz="0" izz=".001" />
    </inertial>
  </link>

  <joint type="continuous" name="right_wheel_hinge">
    <axis xyz="0 1 0" rpy="0 0 0"/>
    <origin xyz="0 -0.245 .095" rpy="0 0 0"/>
    <parent link="base_link"/>
    <child link="right_wheel"/>
    <limit effort="5.2" velocity="21.05"/>
    <joint_properties damping="0.0" friction="0.0"/>
  </joint>

  <link name="yaw_platform">
    <inertial>
      <origin  xyz="0 0 0" rpy="0 0 0" />
      <mass value=".11" />
      <inertia ixx="0.000826" ixy="0" ixz="0" iyy="0.0009211" iyz="0" izz="0.0002601" />
    </inertial>
    <visual>
      <origin xyz="0 0 0" rpy="0 0 1.5708" />
      <geometry>
        <mesh filename="package://robot_sim_demo/meshes/yaw_platform.stl" />
      </geometry>
      <material name="grey"/>
    </visual>
    <collision>
      <origin xyz="0 0 0" rpy="0 0 1.5708" />
      <geometry>
        <mesh filename="package://robot_sim_demo/meshes/yaw_platform.stl" />
      </geometry>
    </collision>
  </link>

  <joint name="base_to_yaw_platform" type="revolute">
    <axis xyz="0 0 1"/>
    <parent link="base_link"/>
    <child link="yaw_platform"/>
    <origin rpy="0 0 0" xyz="0 0 1.07"/>
    <limit effort="100" velocity="100" lower="-1.57" upper="1.57" />
    <dynamics damping="0.0" friction="5.0"/>
  </joint>

  <link name="pitch_platform">
    <inertial>
      <origin  xyz="0 0 0" rpy="0 0 0" />
      <mass value=".05" />
      <inertia ixx="0.0001" ixy="0" ixz="0" iyy="0.00001" iyz="0" izz="0.0001" />
    </inertial>
    <visual>
      <origin xyz="0 0 0" rpy="0 0 0" />
      <geometry>
        <mesh filename="package://robot_sim_demo/meshes/pitch_platform.stl" />
      </geometry>
      <material name="grey"/>
    </visual>
    <collision>
      <origin xyz="0 0 0" rpy="0 0 0" />
      <geometry>
        <mesh filename="package://robot_sim_demo/meshes/pitch_platform.stl" />
      </geometry>
    </collision>
  </link>

  <joint name="yaw_to_pitch_platform" type="revolute">
    <axis xyz="0 1 0"/>
    <parent link="yaw_platform"/>
    <child link="pitch_platform"/>
    <origin rpy="0 0 0" xyz="0 0 .02"/>
    <limit effort="100" velocity="100" lower="-1.57" upper="1.57" />
    <dynamics damping="0.0" friction="5.0"/>
  </joint>

  <!-- Camera -->
  <link name="camera_link">
    <collision>
      <origin xyz="0 0 0" rpy="0 0 0"/>
      <geometry>
        <mesh filename="package://robot_sim_demo/meshes/xtion_pro_camera.dae" />
      </geometry>
    </collision>
    <visual>
      <origin xyz="0 0 0" rpy="0 0 0"/>
      <geometry>
        <mesh filename="package://robot_sim_demo/meshes/xtion_pro_camera.dae" />
      </geometry>
      <material name="gray"/>
    </visual>
    <inertial>
      <mass value="1e-5" />
      <origin xyz="0 0 0" rpy="0 0 0"/>
      <inertia ixx="1e-6" ixy="0" ixz="0" iyy="1e-6" iyz="0" izz="1e-6" />
    </inertial>
  </link>

  <joint name="camera_joint" type="fixed">
    <axis xyz="0 1 0" />
    <origin xyz="0 0 .08" rpy="0 0 0"/>
    <parent link="pitch_platform"/>
    <child link="camera_link"/>
  </joint>

  <!-- generate an optical frame http://www.ros.org/reps/rep-0103.html#suffix-frames
      so that ros and opencv can operate on the camera frame correctly -->
  <joint name="camera_optical_joint" type="fixed">
    <!-- these values have to be these values otherwise the gazebo camera image
        won't be aligned properly with the frame it is supposedly originating from -->
    <origin xyz="0 0 0" rpy="${-pi/2} 0 ${-pi/2}"/>
    <parent link="camera_link"/>
    <child link="camera_link_optical"/>
  </joint>

  <link name="camera_link_optical">
  </link>


  </xacro:macro>
</robot>
